2024-10-08 13:18:58,881 - ERROR - Error capturing network logs.
Traceback (most recent call last):
  File "/mnt/k/automation/Automation_scripts/Base/revised_API_LOG.py", line 35, in __init__
    logs = driver.get_log('performance')
  File "/mnt/k/automation/lib/python3.10/site-packages/selenium/webdriver/remote/webdriver.py", line 1025, in get_log
    return self.execute(Command.GET_LOG, {"type": log_type})["value"]
  File "/mnt/k/automation/lib/python3.10/site-packages/selenium/webdriver/remote/webdriver.py", line 354, in execute
    self.error_handler.check_response(response)
  File "/mnt/k/automation/lib/python3.10/site-packages/selenium/webdriver/remote/errorhandler.py", line 229, in check_response
    raise exception_class(message, screen, stacktrace)
selenium.common.exceptions.InvalidArgumentException: Message: invalid argument: log type 'performance' not found
  (Session info: chrome=129.0.6668.70)
Stacktrace:
#0 0x560958c8102a <unknown>
#1 0x5609589675e0 <unknown>
#2 0x5609589f0e5a <unknown>
#3 0x5609589dbae8 <unknown>
#4 0x5609589a96b3 <unknown>
#5 0x5609589aa68e <unknown>
#6 0x560958c4ba2b <unknown>
#7 0x560958c4f9b1 <unknown>
#8 0x560958c38225 <unknown>
#9 0x560958c50532 <unknown>
#10 0x560958c1d38f <unknown>
#11 0x560958c6ff28 <unknown>
#12 0x560958c700f3 <unknown>
#13 0x560958c7fe7c <unknown>
#14 0x7f049d757ac3 <unknown>

2024-10-08 13:22:58,668 - ERROR - Error capturing network logs.
Traceback (most recent call last):
  File "/mnt/k/automation/Automation_scripts/Base/revised_API_LOG.py", line 33, in __init__
    self.driver = webdriver.Chrome(options=chrome_options)
  File "/mnt/k/automation/lib/python3.10/site-packages/selenium/webdriver/chrome/webdriver.py", line 45, in __init__
    super().__init__(
  File "/mnt/k/automation/lib/python3.10/site-packages/selenium/webdriver/chromium/webdriver.py", line 66, in __init__
    super().__init__(command_executor=executor, options=options)
  File "/mnt/k/automation/lib/python3.10/site-packages/selenium/webdriver/remote/webdriver.py", line 212, in __init__
    self.start_session(capabilities)
  File "/mnt/k/automation/lib/python3.10/site-packages/selenium/webdriver/remote/webdriver.py", line 299, in start_session
    response = self.execute(Command.NEW_SESSION, caps)["value"]
  File "/mnt/k/automation/lib/python3.10/site-packages/selenium/webdriver/remote/webdriver.py", line 354, in execute
    self.error_handler.check_response(response)
  File "/mnt/k/automation/lib/python3.10/site-packages/selenium/webdriver/remote/errorhandler.py", line 229, in check_response
    raise exception_class(message, screen, stacktrace)
selenium.common.exceptions.SessionNotCreatedException: Message: session not created: Missing or invalid capabilities
  (Driver info: chromedriver=129.0.6668.89 (951c0b97221f8d4ba37cf97d324505c832251cf9-refs/branch-heads/6668@{#1503}),platform=Linux 5.15.146.1-microsoft-standard-WSL2 x86_64)

2024-10-08 13:34:06,519 - ERROR - Error capturing network logs.
Traceback (most recent call last):
  File "/mnt/k/automation/Automation_scripts/Base/revised_API_LOG.py", line 36, in __init__
    logs = self.driver.execute_cdp_cmd("Network.getResponseBody", {})  # This is for demonstration
  File "/mnt/k/automation/lib/python3.10/site-packages/selenium/webdriver/chromium/webdriver.py", line 141, in execute_cdp_cmd
    return self.execute("executeCdpCommand", {"cmd": cmd, "params": cmd_args})["value"]
  File "/mnt/k/automation/lib/python3.10/site-packages/selenium/webdriver/remote/webdriver.py", line 354, in execute
    self.error_handler.check_response(response)
  File "/mnt/k/automation/lib/python3.10/site-packages/selenium/webdriver/remote/errorhandler.py", line 229, in check_response
    raise exception_class(message, screen, stacktrace)
selenium.common.exceptions.InvalidArgumentException: Message: invalid argument: Invalid parameters
  (Session info: chrome=129.0.6668.70)
Stacktrace:
#0 0x55ec6e4ae02a <unknown>
#1 0x55ec6e1945e0 <unknown>
#2 0x55ec6e17ba27 <unknown>
#3 0x55ec6e17a3e8 <unknown>
#4 0x55ec6e17ac4f <unknown>
#5 0x55ec6e17aba4 <unknown>
#6 0x55ec6e197c5f <unknown>
#7 0x55ec6e233f9a <unknown>
#8 0x55ec6e208b22 <unknown>
#9 0x55ec6e227d7d <unknown>
#10 0x55ec6e2088c3 <unknown>
#11 0x55ec6e1d66b3 <unknown>
#12 0x55ec6e1d768e <unknown>
#13 0x55ec6e478a2b <unknown>
#14 0x55ec6e47c9b1 <unknown>
#15 0x55ec6e465225 <unknown>
#16 0x55ec6e47d532 <unknown>
#17 0x55ec6e44a38f <unknown>
#18 0x55ec6e49cf28 <unknown>
#19 0x55ec6e49d0f3 <unknown>
#20 0x55ec6e4ace7c <unknown>
#21 0x7f835a349ac3 <unknown>

2024-10-08 13:49:22,800 - ERROR - Error fetching logs.
Traceback (most recent call last):
  File "/mnt/k/automation/Automation_scripts/Base/revised_API_LOG.py", line 42, in fetch_logs
    logs = self.driver.get_log("performance")
  File "/mnt/k/automation/lib/python3.10/site-packages/selenium/webdriver/remote/webdriver.py", line 1025, in get_log
    return self.execute(Command.GET_LOG, {"type": log_type})["value"]
  File "/mnt/k/automation/lib/python3.10/site-packages/selenium/webdriver/remote/webdriver.py", line 354, in execute
    self.error_handler.check_response(response)
  File "/mnt/k/automation/lib/python3.10/site-packages/selenium/webdriver/remote/errorhandler.py", line 229, in check_response
    raise exception_class(message, screen, stacktrace)
selenium.common.exceptions.InvalidArgumentException: Message: invalid argument: log type 'performance' not found
  (Session info: chrome=129.0.6668.70)
Stacktrace:
#0 0x55d19639902a <unknown>
#1 0x55d19607f5e0 <unknown>
#2 0x55d196108e5a <unknown>
#3 0x55d1960f3ae8 <unknown>
#4 0x55d1960c16b3 <unknown>
#5 0x55d1960c268e <unknown>
#6 0x55d196363a2b <unknown>
#7 0x55d1963679b1 <unknown>
#8 0x55d196350225 <unknown>
#9 0x55d196368532 <unknown>
#10 0x55d19633538f <unknown>
#11 0x55d196387f28 <unknown>
#12 0x55d1963880f3 <unknown>
#13 0x55d196397e7c <unknown>
#14 0x7fa0fd2dcac3 <unknown>

2024-10-08 14:52:03,859 - ERROR - Error fetching logs.
Traceback (most recent call last):
  File "/mnt/k/automation/Automation_scripts/Base/revised_API_LOG.py", line 42, in fetch_logs
    logs = self.driver.get_log("performance")
  File "/mnt/k/automation/lib/python3.10/site-packages/selenium/webdriver/remote/webdriver.py", line 1025, in get_log
    return self.execute(Command.GET_LOG, {"type": log_type})["value"]
  File "/mnt/k/automation/lib/python3.10/site-packages/selenium/webdriver/remote/webdriver.py", line 354, in execute
    self.error_handler.check_response(response)
  File "/mnt/k/automation/lib/python3.10/site-packages/selenium/webdriver/remote/errorhandler.py", line 229, in check_response
    raise exception_class(message, screen, stacktrace)
selenium.common.exceptions.InvalidArgumentException: Message: invalid argument: log type 'performance' not found
  (Session info: chrome=129.0.6668.70)
Stacktrace:
#0 0x55f7e6ded02a <unknown>
#1 0x55f7e6ad35e0 <unknown>
#2 0x55f7e6b5ce5a <unknown>
#3 0x55f7e6b47ae8 <unknown>
#4 0x55f7e6b156b3 <unknown>
#5 0x55f7e6b1668e <unknown>
#6 0x55f7e6db7a2b <unknown>
#7 0x55f7e6dbb9b1 <unknown>
#8 0x55f7e6da4225 <unknown>
#9 0x55f7e6dbc532 <unknown>
#10 0x55f7e6d8938f <unknown>
#11 0x55f7e6ddbf28 <unknown>
#12 0x55f7e6ddc0f3 <unknown>
#13 0x55f7e6debe7c <unknown>
#14 0x7ff649787ac3 <unknown>

2024-10-08 15:10:48,567 - ERROR - Error fetching logs.
Traceback (most recent call last):
  File "/mnt/k/automation/Automation_scripts/Base/revised_API_LOG.py", line 42, in fetch_logs
    logs = self.driver.get_log("performance")
  File "/mnt/k/automation/lib/python3.10/site-packages/selenium/webdriver/remote/webdriver.py", line 1025, in get_log
    return self.execute(Command.GET_LOG, {"type": log_type})["value"]
  File "/mnt/k/automation/lib/python3.10/site-packages/selenium/webdriver/remote/webdriver.py", line 354, in execute
    self.error_handler.check_response(response)
  File "/mnt/k/automation/lib/python3.10/site-packages/selenium/webdriver/remote/errorhandler.py", line 229, in check_response
    raise exception_class(message, screen, stacktrace)
selenium.common.exceptions.InvalidArgumentException: Message: invalid argument: log type 'performance' not found
  (Session info: chrome=129.0.6668.70)
Stacktrace:
#0 0x5609d9cd302a <unknown>
#1 0x5609d99b95e0 <unknown>
#2 0x5609d9a42e5a <unknown>
#3 0x5609d9a2dae8 <unknown>
#4 0x5609d99fb6b3 <unknown>
#5 0x5609d99fc68e <unknown>
#6 0x5609d9c9da2b <unknown>
#7 0x5609d9ca19b1 <unknown>
#8 0x5609d9c8a225 <unknown>
#9 0x5609d9ca2532 <unknown>
#10 0x5609d9c6f38f <unknown>
#11 0x5609d9cc1f28 <unknown>
#12 0x5609d9cc20f3 <unknown>
#13 0x5609d9cd1e7c <unknown>
#14 0x7f16be751ac3 <unknown>

2024-10-08 15:22:54,773 - ERROR - Error fetching logs.
Traceback (most recent call last):
  File "/mnt/k/automation/Automation_scripts/Base/revised_API_LOG.py", line 42, in fetch_logs
    logs = self.driver.get_log("performance")
  File "/mnt/k/automation/lib/python3.10/site-packages/selenium/webdriver/remote/webdriver.py", line 1025, in get_log
    return self.execute(Command.GET_LOG, {"type": log_type})["value"]
  File "/mnt/k/automation/lib/python3.10/site-packages/selenium/webdriver/remote/webdriver.py", line 354, in execute
    self.error_handler.check_response(response)
  File "/mnt/k/automation/lib/python3.10/site-packages/selenium/webdriver/remote/errorhandler.py", line 229, in check_response
    raise exception_class(message, screen, stacktrace)
selenium.common.exceptions.InvalidArgumentException: Message: invalid argument: log type 'performance' not found
  (Session info: chrome=129.0.6668.70)
Stacktrace:
#0 0x559f5e44902a <unknown>
#1 0x559f5e12f5e0 <unknown>
#2 0x559f5e1b8e5a <unknown>
#3 0x559f5e1a3ae8 <unknown>
#4 0x559f5e1716b3 <unknown>
#5 0x559f5e17268e <unknown>
#6 0x559f5e413a2b <unknown>
#7 0x559f5e4179b1 <unknown>
#8 0x559f5e400225 <unknown>
#9 0x559f5e418532 <unknown>
#10 0x559f5e3e538f <unknown>
#11 0x559f5e437f28 <unknown>
#12 0x559f5e4380f3 <unknown>
#13 0x559f5e447e7c <unknown>
#14 0x7fd55f4d7ac3 <unknown>

2024-10-08 15:28:58,111 - ERROR - Error fetching logs.
Traceback (most recent call last):
  File "/mnt/k/automation/Automation_scripts/Base/revised_API_LOG.py", line 42, in fetch_logs
    logs = self.driver.get_log("performance")
  File "/mnt/k/automation/lib/python3.10/site-packages/selenium/webdriver/remote/webdriver.py", line 1025, in get_log
    return self.execute(Command.GET_LOG, {"type": log_type})["value"]
  File "/mnt/k/automation/lib/python3.10/site-packages/selenium/webdriver/remote/webdriver.py", line 354, in execute
    self.error_handler.check_response(response)
  File "/mnt/k/automation/lib/python3.10/site-packages/selenium/webdriver/remote/errorhandler.py", line 229, in check_response
    raise exception_class(message, screen, stacktrace)
selenium.common.exceptions.InvalidArgumentException: Message: invalid argument: log type 'performance' not found
  (Session info: chrome=129.0.6668.70)
Stacktrace:
#0 0x55f9c04f802a <unknown>
#1 0x55f9c01de5e0 <unknown>
#2 0x55f9c0267e5a <unknown>
#3 0x55f9c0252ae8 <unknown>
#4 0x55f9c02206b3 <unknown>
#5 0x55f9c022168e <unknown>
#6 0x55f9c04c2a2b <unknown>
#7 0x55f9c04c69b1 <unknown>
#8 0x55f9c04af225 <unknown>
#9 0x55f9c04c7532 <unknown>
#10 0x55f9c049438f <unknown>
#11 0x55f9c04e6f28 <unknown>
#12 0x55f9c04e70f3 <unknown>
#13 0x55f9c04f6e7c <unknown>
#14 0x7fa0e1ed2ac3 <unknown>

2024-10-08 15:38:21,260 - ERROR - Error fetching logs.
Traceback (most recent call last):
  File "/mnt/k/automation/Automation_scripts/Base/revised_API_LOG.py", line 42, in fetch_logs
    logs = self.driver.get_log("performance")
  File "/mnt/k/automation/lib/python3.10/site-packages/selenium/webdriver/remote/webdriver.py", line 1025, in get_log
    return self.execute(Command.GET_LOG, {"type": log_type})["value"]
  File "/mnt/k/automation/lib/python3.10/site-packages/selenium/webdriver/remote/webdriver.py", line 354, in execute
    self.error_handler.check_response(response)
  File "/mnt/k/automation/lib/python3.10/site-packages/selenium/webdriver/remote/errorhandler.py", line 229, in check_response
    raise exception_class(message, screen, stacktrace)
selenium.common.exceptions.InvalidArgumentException: Message: invalid argument: log type 'performance' not found
  (Session info: chrome=129.0.6668.70)
Stacktrace:
#0 0x55ae1b10202a <unknown>
#1 0x55ae1ade85e0 <unknown>
#2 0x55ae1ae71e5a <unknown>
#3 0x55ae1ae5cae8 <unknown>
#4 0x55ae1ae2a6b3 <unknown>
#5 0x55ae1ae2b68e <unknown>
#6 0x55ae1b0cca2b <unknown>
#7 0x55ae1b0d09b1 <unknown>
#8 0x55ae1b0b9225 <unknown>
#9 0x55ae1b0d1532 <unknown>
#10 0x55ae1b09e38f <unknown>
#11 0x55ae1b0f0f28 <unknown>
#12 0x55ae1b0f10f3 <unknown>
#13 0x55ae1b100e7c <unknown>
#14 0x7fd2f3fd5ac3 <unknown>

2024-10-08 15:45:41,937 - ERROR - Error fetching logs.
Traceback (most recent call last):
  File "/mnt/k/automation/Automation_scripts/Base/revised_API_LOG.py", line 42, in fetch_logs
    logs = self.driver.get_log("performance")
  File "/mnt/k/automation/lib/python3.10/site-packages/selenium/webdriver/remote/webdriver.py", line 1025, in get_log
    return self.execute(Command.GET_LOG, {"type": log_type})["value"]
  File "/mnt/k/automation/lib/python3.10/site-packages/selenium/webdriver/remote/webdriver.py", line 354, in execute
    self.error_handler.check_response(response)
  File "/mnt/k/automation/lib/python3.10/site-packages/selenium/webdriver/remote/errorhandler.py", line 229, in check_response
    raise exception_class(message, screen, stacktrace)
selenium.common.exceptions.InvalidArgumentException: Message: invalid argument: log type 'performance' not found
  (Session info: chrome=129.0.6668.70)
Stacktrace:
#0 0x5583012b102a <unknown>
#1 0x558300f975e0 <unknown>
#2 0x558301020e5a <unknown>
#3 0x55830100bae8 <unknown>
#4 0x558300fd96b3 <unknown>
#5 0x558300fda68e <unknown>
#6 0x55830127ba2b <unknown>
#7 0x55830127f9b1 <unknown>
#8 0x558301268225 <unknown>
#9 0x558301280532 <unknown>
#10 0x55830124d38f <unknown>
#11 0x55830129ff28 <unknown>
#12 0x5583012a00f3 <unknown>
#13 0x5583012afe7c <unknown>
#14 0x7fcde5201ac3 <unknown>

2024-10-09 10:48:34,629 - ERROR - Error fetching logs.
Traceback (most recent call last):
  File "/mnt/k/automation/Automation_scripts/Base/revised_API_LOG.py", line 42, in fetch_logs
    logs = self.driver.get_log("performance")
  File "/mnt/k/automation/lib/python3.10/site-packages/selenium/webdriver/remote/webdriver.py", line 1025, in get_log
    return self.execute(Command.GET_LOG, {"type": log_type})["value"]
  File "/mnt/k/automation/lib/python3.10/site-packages/selenium/webdriver/remote/webdriver.py", line 354, in execute
    self.error_handler.check_response(response)
  File "/mnt/k/automation/lib/python3.10/site-packages/selenium/webdriver/remote/errorhandler.py", line 229, in check_response
    raise exception_class(message, screen, stacktrace)
selenium.common.exceptions.InvalidArgumentException: Message: invalid argument: log type 'performance' not found
  (Session info: chrome=129.0.6668.70)
Stacktrace:
#0 0x5579fd5a0f8a <unknown>
#1 0x5579fd2875e0 <unknown>
#2 0x5579fd310e5a <unknown>
#3 0x5579fd2fbae8 <unknown>
#4 0x5579fd2c96b3 <unknown>
#5 0x5579fd2ca68e <unknown>
#6 0x5579fd56b98b <unknown>
#7 0x5579fd56f911 <unknown>
#8 0x5579fd558185 <unknown>
#9 0x5579fd570492 <unknown>
#10 0x5579fd53d2ef <unknown>
#11 0x5579fd58fe88 <unknown>
#12 0x5579fd590053 <unknown>
#13 0x5579fd59fddc <unknown>
#14 0x7ffa67f49ac3 <unknown>

2024-10-09 10:52:56,780 - ERROR - Error fetching logs.
Traceback (most recent call last):
  File "/mnt/k/automation/Automation_scripts/Base/revised_API_LOG.py", line 42, in fetch_logs
    logs = self.driver.get_log("performance")
  File "/mnt/k/automation/lib/python3.10/site-packages/selenium/webdriver/remote/webdriver.py", line 1025, in get_log
    return self.execute(Command.GET_LOG, {"type": log_type})["value"]
  File "/mnt/k/automation/lib/python3.10/site-packages/selenium/webdriver/remote/webdriver.py", line 354, in execute
    self.error_handler.check_response(response)
  File "/mnt/k/automation/lib/python3.10/site-packages/selenium/webdriver/remote/errorhandler.py", line 229, in check_response
    raise exception_class(message, screen, stacktrace)
selenium.common.exceptions.InvalidArgumentException: Message: invalid argument: log type 'performance' not found
  (Session info: chrome=129.0.6668.70)
Stacktrace:
#0 0x562b71e7af8a <unknown>
#1 0x562b71b615e0 <unknown>
#2 0x562b71beae5a <unknown>
#3 0x562b71bd5ae8 <unknown>
#4 0x562b71ba36b3 <unknown>
#5 0x562b71ba468e <unknown>
#6 0x562b71e4598b <unknown>
#7 0x562b71e49911 <unknown>
#8 0x562b71e32185 <unknown>
#9 0x562b71e4a492 <unknown>
#10 0x562b71e172ef <unknown>
#11 0x562b71e69e88 <unknown>
#12 0x562b71e6a053 <unknown>
#13 0x562b71e79ddc <unknown>
#14 0x7f78dffefac3 <unknown>

2024-10-09 10:56:30,013 - ERROR - Error fetching logs.
Traceback (most recent call last):
  File "/mnt/k/automation/Automation_scripts/Base/revised_API_LOG.py", line 42, in fetch_logs
    logs = self.driver.get_log()
TypeError: WebDriver.get_log() missing 1 required positional argument: 'log_type'
2024-10-09 10:58:24,455 - ERROR - Error fetching logs.
Traceback (most recent call last):
  File "/mnt/k/automation/Automation_scripts/Base/revised_API_LOG.py", line 42, in fetch_logs
    logs = self.driver.get_log()
TypeError: WebDriver.get_log() missing 1 required positional argument: 'log_type'
2024-10-09 11:05:46,549 - ERROR - Error fetching logs.
Traceback (most recent call last):
  File "/mnt/k/automation/Automation_scripts/Base/revised_API_LOG.py", line 42, in fetch_logs
    logs = self.driver.get_log('performance')
  File "/mnt/k/automation/lib/python3.10/site-packages/selenium/webdriver/remote/webdriver.py", line 1025, in get_log
    return self.execute(Command.GET_LOG, {"type": log_type})["value"]
  File "/mnt/k/automation/lib/python3.10/site-packages/selenium/webdriver/remote/webdriver.py", line 354, in execute
    self.error_handler.check_response(response)
  File "/mnt/k/automation/lib/python3.10/site-packages/selenium/webdriver/remote/errorhandler.py", line 229, in check_response
    raise exception_class(message, screen, stacktrace)
selenium.common.exceptions.InvalidArgumentException: Message: invalid argument: log type 'performance' not found
  (Session info: chrome=129.0.6668.70)
Stacktrace:
#0 0x55ba9a2a3f8a <unknown>
#1 0x55ba99f8a5e0 <unknown>
#2 0x55ba9a013e5a <unknown>
#3 0x55ba99ffeae8 <unknown>
#4 0x55ba99fcc6b3 <unknown>
#5 0x55ba99fcd68e <unknown>
#6 0x55ba9a26e98b <unknown>
#7 0x55ba9a272911 <unknown>
#8 0x55ba9a25b185 <unknown>
#9 0x55ba9a273492 <unknown>
#10 0x55ba9a2402ef <unknown>
#11 0x55ba9a292e88 <unknown>
#12 0x55ba9a293053 <unknown>
#13 0x55ba9a2a2ddc <unknown>
#14 0x7f2c8046eac3 <unknown>

2024-10-09 11:08:09,148 - ERROR - Error fetching logs.
Traceback (most recent call last):
  File "/mnt/k/automation/Automation_scripts/Base/revised_API_LOG.py", line 47, in fetch_logs
    response = message['params']['response']
KeyError: 'response'
2024-10-09 18:20:29,207 - ERROR - Error fetching logs.
Traceback (most recent call last):
  File "/mnt/k/automation/Automation_scripts/Base/revised_API_LOG.py", line 47, in fetch_logs
    response = message['params']['response']
KeyError: 'response'
2024-10-09 18:30:55,084 - ERROR - Error fetching logs.
Traceback (most recent call last):
  File "/mnt/k/automation/Automation_scripts/Base/revised_API_LOG.py", line 47, in fetch_logs
    response = message['params']['response']
KeyError: 'response'
2024-10-09 18:37:07,106 - ERROR - Error fetching logs.
Traceback (most recent call last):
  File "/mnt/k/automation/Automation_scripts/Base/revised_API_LOG.py", line 47, in fetch_logs
    response = message['params']['response']
KeyError: 'response'
2024-10-09 18:42:09,885 - ERROR - Error fetching logs.
Traceback (most recent call last):
  File "/mnt/k/automation/Automation_scripts/Base/revised_API_LOG.py", line 47, in fetch_logs
    response = message['params']['response']
KeyError: 'response'
2024-10-09 18:46:12,759 - ERROR - Error fetching logs.
Traceback (most recent call last):
  File "/mnt/k/automation/Automation_scripts/Base/revised_API_LOG.py", line 47, in fetch_logs
    response = message['params']['response']
KeyError: 'response'
2024-10-09 18:51:08,742 - ERROR - Error fetching logs.
Traceback (most recent call last):
  File "/mnt/k/automation/Automation_scripts/Base/revised_API_LOG.py", line 47, in fetch_logs
    response = message['params']['response']
KeyError: 'response'
2024-10-09 18:58:31,991 - ERROR - Error fetching logs.
Traceback (most recent call last):
  File "/mnt/k/automation/Automation_scripts/Base/revised_API_LOG.py", line 47, in fetch_logs
    response = message['params']['response']
KeyError: 'response'
2024-10-09 19:14:30,764 - ERROR - Error fetching logs.
Traceback (most recent call last):
  File "/mnt/k/automation/Automation_scripts/Base/revised_API_LOG.py", line 47, in fetch_logs
    response = message['params']['response']
KeyError: 'response'
